[2025-04-09 11:05:27 +0000] [7] [INFO] Starting gunicorn 23.0.0
[2025-04-09 11:05:27 +0000] [7] [INFO] Listening at: http://0.0.0.0:5000 (7)
[2025-04-09 11:05:27 +0000] [7] [INFO] Using worker: sync
[2025-04-09 11:05:27 +0000] [8] [INFO] Booting worker with pid: 8
[2025-04-09 11:05:27 +0000] [24] [INFO] Booting worker with pid: 24
[2025-04-09 11:05:27 +0000] [25] [INFO] Booting worker with pid: 25
[2025-04-09 11:05:27 +0000] [56] [INFO] Booting worker with pid: 56
[2025-04-09 11:05:30 +0000] [24] [ERROR] Exception in worker process
Traceback (most recent call last):
  File "/usr/local/lib/python3.10/site-packages/gunicorn/arbiter.py", line 608, in spawn_worker
    worker.init_process()
  File "/usr/local/lib/python3.10/site-packages/gunicorn/workers/base.py", line 135, in init_process
    self.load_wsgi()
  File "/usr/local/lib/python3.10/site-packages/gunicorn/workers/base.py", line 147, in load_wsgi
    self.wsgi = self.app.wsgi()
  File "/usr/local/lib/python3.10/site-packages/gunicorn/app/base.py", line 66, in wsgi
    self.callable = self.load()
  File "/usr/local/lib/python3.10/site-packages/gunicorn/app/wsgiapp.py", line 57, in load
    return self.load_wsgiapp()
  File "/usr/local/lib/python3.10/site-packages/gunicorn/app/wsgiapp.py", line 47, in load_wsgiapp
    return util.import_app(self.app_uri)
  File "/usr/local/lib/python3.10/site-packages/gunicorn/util.py", line 370, in import_app
    mod = importlib.import_module(module)
  File "/usr/local/lib/python3.10/importlib/__init__.py", line 126, in import_module
    return _bootstrap._gcd_import(name[level:], package, level)
  File "<frozen importlib._bootstrap>", line 1050, in _gcd_import
  File "<frozen importlib._bootstrap>", line 1027, in _find_and_load
  File "<frozen importlib._bootstrap>", line 1006, in _find_and_load_unlocked
  File "<frozen importlib._bootstrap>", line 688, in _load_unlocked
  File "<frozen importlib._bootstrap_external>", line 883, in exec_module
  File "<frozen importlib._bootstrap>", line 241, in _call_with_frames_removed
  File "/home/app/app.py", line 14, in <module>
    model = YOLOv10(r'G:\inference_recognition\runs\detect\train10\weights\best.pt')
  File "/home/app/ultralytics/models/yolov10/model.py", line 14, in __init__
    super().__init__(model=model, task=task, verbose=verbose)
  File "/home/app/ultralytics/engine/model.py", line 141, in __init__
    self._load(model, task=task)
  File "/home/app/ultralytics/engine/model.py", line 230, in _load
    self.model, self.ckpt = attempt_load_one_weight(weights)
  File "/home/app/ultralytics/nn/tasks.py", line 807, in attempt_load_one_weight
    ckpt, weight = torch_safe_load(weight)  # load ckpt
  File "/home/app/ultralytics/nn/tasks.py", line 733, in torch_safe_load
    ckpt = torch.load(file, map_location="cpu")
  File "/usr/local/lib/python3.10/site-packages/torch/serialization.py", line 791, in load
    with _open_file_like(f, 'rb') as opened_file:
  File "/usr/local/lib/python3.10/site-packages/torch/serialization.py", line 271, in _open_file_like
    return _open_file(name_or_buffer, mode)
  File "/usr/local/lib/python3.10/site-packages/torch/serialization.py", line 252, in __init__
    super().__init__(open(name, mode))
FileNotFoundError: [Errno 2] No such file or directory: 'G:\\inference_recognition\\runs\\detect\\train10\\weights\\best.pt'
[2025-04-09 11:05:30 +0000] [25] [ERROR] Exception in worker process
Traceback (most recent call last):
  File "/usr/local/lib/python3.10/site-packages/gunicorn/arbiter.py", line 608, in spawn_worker
    worker.init_process()
  File "/usr/local/lib/python3.10/site-packages/gunicorn/workers/base.py", line 135, in init_process
    self.load_wsgi()
  File "/usr/local/lib/python3.10/site-packages/gunicorn/workers/base.py", line 147, in load_wsgi
    self.wsgi = self.app.wsgi()
  File "/usr/local/lib/python3.10/site-packages/gunicorn/app/base.py", line 66, in wsgi
    self.callable = self.load()
  File "/usr/local/lib/python3.10/site-packages/gunicorn/app/wsgiapp.py", line 57, in load
    return self.load_wsgiapp()
  File "/usr/local/lib/python3.10/site-packages/gunicorn/app/wsgiapp.py", line 47, in load_wsgiapp
    return util.import_app(self.app_uri)
  File "/usr/local/lib/python3.10/site-packages/gunicorn/util.py", line 370, in import_app
    mod = importlib.import_module(module)
  File "/usr/local/lib/python3.10/importlib/__init__.py", line 126, in import_module
    return _bootstrap._gcd_import(name[level:], package, level)
  File "<frozen importlib._bootstrap>", line 1050, in _gcd_import
  File "<frozen importlib._bootstrap>", line 1027, in _find_and_load
  File "<frozen importlib._bootstrap>", line 1006, in _find_and_load_unlocked
  File "<frozen importlib._bootstrap>", line 688, in _load_unlocked
  File "<frozen importlib._bootstrap_external>", line 883, in exec_module
  File "<frozen importlib._bootstrap>", line 241, in _call_with_frames_removed
  File "/home/app/app.py", line 14, in <module>
    model = YOLOv10(r'G:\inference_recognition\runs\detect\train10\weights\best.pt')
  File "/home/app/ultralytics/models/yolov10/model.py", line 14, in __init__
    super().__init__(model=model, task=task, verbose=verbose)
  File "/home/app/ultralytics/engine/model.py", line 141, in __init__
    self._load(model, task=task)
  File "/home/app/ultralytics/engine/model.py", line 230, in _load
    self.model, self.ckpt = attempt_load_one_weight(weights)
  File "/home/app/ultralytics/nn/tasks.py", line 807, in attempt_load_one_weight
    ckpt, weight = torch_safe_load(weight)  # load ckpt
  File "/home/app/ultralytics/nn/tasks.py", line 733, in torch_safe_load
    ckpt = torch.load(file, map_location="cpu")
  File "/usr/local/lib/python3.10/site-packages/torch/serialization.py", line 791, in load
    with _open_file_like(f, 'rb') as opened_file:
  File "/usr/local/lib/python3.10/site-packages/torch/serialization.py", line 271, in _open_file_like
    return _open_file(name_or_buffer, mode)
  File "/usr/local/lib/python3.10/site-packages/torch/serialization.py", line 252, in __init__
    super().__init__(open(name, mode))
FileNotFoundError: [Errno 2] No such file or directory: 'G:\\inference_recognition\\runs\\detect\\train10\\weights\\best.pt'
[2025-04-09 11:05:30 +0000] [24] [INFO] Worker exiting (pid: 24)
[2025-04-09 11:05:30 +0000] [25] [INFO] Worker exiting (pid: 25)
[2025-04-09 11:05:30 +0000] [8] [ERROR] Exception in worker process
Traceback (most recent call last):
  File "/usr/local/lib/python3.10/site-packages/gunicorn/arbiter.py", line 608, in spawn_worker
    worker.init_process()
  File "/usr/local/lib/python3.10/site-packages/gunicorn/workers/base.py", line 135, in init_process
    self.load_wsgi()
  File "/usr/local/lib/python3.10/site-packages/gunicorn/workers/base.py", line 147, in load_wsgi
    self.wsgi = self.app.wsgi()
  File "/usr/local/lib/python3.10/site-packages/gunicorn/app/base.py", line 66, in wsgi
    self.callable = self.load()
  File "/usr/local/lib/python3.10/site-packages/gunicorn/app/wsgiapp.py", line 57, in load
    return self.load_wsgiapp()
  File "/usr/local/lib/python3.10/site-packages/gunicorn/app/wsgiapp.py", line 47, in load_wsgiapp
    return util.import_app(self.app_uri)
  File "/usr/local/lib/python3.10/site-packages/gunicorn/util.py", line 370, in import_app
    mod = importlib.import_module(module)
  File "/usr/local/lib/python3.10/importlib/__init__.py", line 126, in import_module
    return _bootstrap._gcd_import(name[level:], package, level)
  File "<frozen importlib._bootstrap>", line 1050, in _gcd_import
  File "<frozen importlib._bootstrap>", line 1027, in _find_and_load
  File "<frozen importlib._bootstrap>", line 1006, in _find_and_load_unlocked
  File "<frozen importlib._bootstrap>", line 688, in _load_unlocked
  File "<frozen importlib._bootstrap_external>", line 883, in exec_module
  File "<frozen importlib._bootstrap>", line 241, in _call_with_frames_removed
  File "/home/app/app.py", line 14, in <module>
    model = YOLOv10(r'G:\inference_recognition\runs\detect\train10\weights\best.pt')
  File "/home/app/ultralytics/models/yolov10/model.py", line 14, in __init__
    super().__init__(model=model, task=task, verbose=verbose)
  File "/home/app/ultralytics/engine/model.py", line 141, in __init__
    self._load(model, task=task)
  File "/home/app/ultralytics/engine/model.py", line 230, in _load
    self.model, self.ckpt = attempt_load_one_weight(weights)
  File "/home/app/ultralytics/nn/tasks.py", line 807, in attempt_load_one_weight
    ckpt, weight = torch_safe_load(weight)  # load ckpt
  File "/home/app/ultralytics/nn/tasks.py", line 733, in torch_safe_load
    ckpt = torch.load(file, map_location="cpu")
  File "/usr/local/lib/python3.10/site-packages/torch/serialization.py", line 791, in load
    with _open_file_like(f, 'rb') as opened_file:
  File "/usr/local/lib/python3.10/site-packages/torch/serialization.py", line 271, in _open_file_like
    return _open_file(name_or_buffer, mode)
  File "/usr/local/lib/python3.10/site-packages/torch/serialization.py", line 252, in __init__
    super().__init__(open(name, mode))
FileNotFoundError: [Errno 2] No such file or directory: 'G:\\inference_recognition\\runs\\detect\\train10\\weights\\best.pt'
[2025-04-09 11:05:30 +0000] [8] [INFO] Worker exiting (pid: 8)
[2025-04-09 11:05:30 +0000] [56] [ERROR] Exception in worker process
Traceback (most recent call last):
  File "/usr/local/lib/python3.10/site-packages/gunicorn/arbiter.py", line 608, in spawn_worker
    worker.init_process()
  File "/usr/local/lib/python3.10/site-packages/gunicorn/workers/base.py", line 135, in init_process
    self.load_wsgi()
  File "/usr/local/lib/python3.10/site-packages/gunicorn/workers/base.py", line 147, in load_wsgi
    self.wsgi = self.app.wsgi()
  File "/usr/local/lib/python3.10/site-packages/gunicorn/app/base.py", line 66, in wsgi
    self.callable = self.load()
  File "/usr/local/lib/python3.10/site-packages/gunicorn/app/wsgiapp.py", line 57, in load
    return self.load_wsgiapp()
  File "/usr/local/lib/python3.10/site-packages/gunicorn/app/wsgiapp.py", line 47, in load_wsgiapp
    return util.import_app(self.app_uri)
  File "/usr/local/lib/python3.10/site-packages/gunicorn/util.py", line 370, in import_app
    mod = importlib.import_module(module)
  File "/usr/local/lib/python3.10/importlib/__init__.py", line 126, in import_module
    return _bootstrap._gcd_import(name[level:], package, level)
  File "<frozen importlib._bootstrap>", line 1050, in _gcd_import
  File "<frozen importlib._bootstrap>", line 1027, in _find_and_load
  File "<frozen importlib._bootstrap>", line 1006, in _find_and_load_unlocked
  File "<frozen importlib._bootstrap>", line 688, in _load_unlocked
  File "<frozen importlib._bootstrap_external>", line 883, in exec_module
  File "<frozen importlib._bootstrap>", line 241, in _call_with_frames_removed
  File "/home/app/app.py", line 14, in <module>
    model = YOLOv10(r'G:\inference_recognition\runs\detect\train10\weights\best.pt')
  File "/home/app/ultralytics/models/yolov10/model.py", line 14, in __init__
    super().__init__(model=model, task=task, verbose=verbose)
  File "/home/app/ultralytics/engine/model.py", line 141, in __init__
    self._load(model, task=task)
  File "/home/app/ultralytics/engine/model.py", line 230, in _load
    self.model, self.ckpt = attempt_load_one_weight(weights)
  File "/home/app/ultralytics/nn/tasks.py", line 807, in attempt_load_one_weight
    ckpt, weight = torch_safe_load(weight)  # load ckpt
  File "/home/app/ultralytics/nn/tasks.py", line 733, in torch_safe_load
    ckpt = torch.load(file, map_location="cpu")
  File "/usr/local/lib/python3.10/site-packages/torch/serialization.py", line 791, in load
    with _open_file_like(f, 'rb') as opened_file:
  File "/usr/local/lib/python3.10/site-packages/torch/serialization.py", line 271, in _open_file_like
    return _open_file(name_or_buffer, mode)
  File "/usr/local/lib/python3.10/site-packages/torch/serialization.py", line 252, in __init__
    super().__init__(open(name, mode))
FileNotFoundError: [Errno 2] No such file or directory: 'G:\\inference_recognition\\runs\\detect\\train10\\weights\\best.pt'
[2025-04-09 11:05:30 +0000] [56] [INFO] Worker exiting (pid: 56)
[2025-04-09 11:05:31 +0000] [7] [ERROR] Worker (pid:56) exited with code 3
[2025-04-09 11:05:31 +0000] [7] [ERROR] Worker (pid:8) exited with code 3
Traceback (most recent call last):
  File "/usr/local/lib/python3.10/site-packages/gunicorn/arbiter.py", line 208, in run
    self.sleep()
  File "/usr/local/lib/python3.10/site-packages/gunicorn/arbiter.py", line 359, in sleep
    ready = select.select([self.PIPE[0]], [], [], 1.0)
  File "/usr/local/lib/python3.10/site-packages/gunicorn/arbiter.py", line 241, in handle_chld
    self.reap_workers()
  File "/usr/local/lib/python3.10/site-packages/gunicorn/arbiter.py", line 529, in reap_workers
    raise HaltServer(reason, self.WORKER_BOOT_ERROR)
gunicorn.errors.HaltServer: <HaltServer 'Worker failed to boot.' 3>

During handling of the above exception, another exception occurred:

Traceback (most recent call last):
  File "/usr/local/bin/gunicorn", line 8, in <module>
    sys.exit(run())
  File "/usr/local/lib/python3.10/site-packages/gunicorn/app/wsgiapp.py", line 66, in run
    WSGIApplication("%(prog)s [OPTIONS] [APP_MODULE]", prog=prog).run()
  File "/usr/local/lib/python3.10/site-packages/gunicorn/app/base.py", line 235, in run
    super().run()
  File "/usr/local/lib/python3.10/site-packages/gunicorn/app/base.py", line 71, in run
    Arbiter(self).run()
  File "/usr/local/lib/python3.10/site-packages/gunicorn/arbiter.py", line 228, in run
    self.halt(reason=inst.reason, exit_status=inst.exit_status)
  File "/usr/local/lib/python3.10/site-packages/gunicorn/arbiter.py", line 341, in halt
    self.stop()
  File "/usr/local/lib/python3.10/site-packages/gunicorn/arbiter.py", line 395, in stop
    time.sleep(0.1)
  File "/usr/local/lib/python3.10/site-packages/gunicorn/arbiter.py", line 241, in handle_chld
    self.reap_workers()
  File "/usr/local/lib/python3.10/site-packages/gunicorn/arbiter.py", line 529, in reap_workers
    raise HaltServer(reason, self.WORKER_BOOT_ERROR)
gunicorn.errors.HaltServer: <HaltServer 'Worker failed to boot.' 3>
